2020-11-06 19:21:43,206 ERROR: Exception on /images/db/Aslam [GET] [in /data/data/com.termux/files/usr/lib/python3.9/site-packages/flask/app.py:1758]
Traceback (most recent call last):
  File "/data/data/com.termux/files/usr/lib/python3.9/site-packages/flask/app.py", line 2292, in wsgi_app
    response = self.full_dispatch_request()
  File "/data/data/com.termux/files/usr/lib/python3.9/site-packages/flask/app.py", line 1815, in full_dispatch_request
    rv = self.handle_user_exception(e)
  File "/data/data/com.termux/files/usr/lib/python3.9/site-packages/flask/app.py", line 1718, in handle_user_exception
    reraise(exc_type, exc_value, tb)
  File "/data/data/com.termux/files/usr/lib/python3.9/site-packages/flask/_compat.py", line 35, in reraise
    raise value
  File "/data/data/com.termux/files/usr/lib/python3.9/site-packages/flask/app.py", line 1813, in full_dispatch_request
    rv = self.dispatch_request()
  File "/data/data/com.termux/files/usr/lib/python3.9/site-packages/flask/app.py", line 1799, in dispatch_request
    return self.view_functions[rule.endpoint](**req.view_args)
  File "/storage/emulated/0/python/microblog/app/routes.py", line 212, in get_image_from_db
    image = Image.query.filter_by(author=user).first()
  File "/data/data/com.termux/files/usr/lib/python3.9/site-packages/PIL/Image.py", line 62, in __getattr__
    raise AttributeError(f"module '{__name__}' has no attribute '{name}'")
AttributeError: module 'PIL.Image' has no attribute 'query'
2020-11-06 19:21:57,134 ERROR: Exception on /images/db/Aslam [GET] [in /data/data/com.termux/files/usr/lib/python3.9/site-packages/flask/app.py:1758]
Traceback (most recent call last):
  File "/data/data/com.termux/files/usr/lib/python3.9/site-packages/flask/app.py", line 2292, in wsgi_app
    response = self.full_dispatch_request()
  File "/data/data/com.termux/files/usr/lib/python3.9/site-packages/flask/app.py", line 1815, in full_dispatch_request
    rv = self.handle_user_exception(e)
  File "/data/data/com.termux/files/usr/lib/python3.9/site-packages/flask/app.py", line 1718, in handle_user_exception
    reraise(exc_type, exc_value, tb)
  File "/data/data/com.termux/files/usr/lib/python3.9/site-packages/flask/_compat.py", line 35, in reraise
    raise value
  File "/data/data/com.termux/files/usr/lib/python3.9/site-packages/flask/app.py", line 1813, in full_dispatch_request
    rv = self.dispatch_request()
  File "/data/data/com.termux/files/usr/lib/python3.9/site-packages/flask/app.py", line 1799, in dispatch_request
    return self.view_functions[rule.endpoint](**req.view_args)
  File "/storage/emulated/0/python/microblog/app/routes.py", line 212, in get_image_from_db
    image = Image.query.filter_by(author=user).first()
  File "/data/data/com.termux/files/usr/lib/python3.9/site-packages/PIL/Image.py", line 62, in __getattr__
    raise AttributeError(f"module '{__name__}' has no attribute '{name}'")
AttributeError: module 'PIL.Image' has no attribute 'query'
2020-11-06 20:12:33,407 INFO: Microblog startup [in /storage/emulated/0/python/microblog/app/__init__.py:50]
2020-11-06 20:12:38,201 INFO: Microblog startup [in /storage/emulated/0/python/microblog/app/__init__.py:50]
2020-11-06 20:12:44,258 INFO: Microblog startup [in /storage/emulated/0/python/microblog/app/__init__.py:50]
2020-11-06 20:12:49,279 ERROR: Exception on /index [GET] [in /data/data/com.termux/files/usr/lib/python3.9/site-packages/flask/app.py:1758]
Traceback (most recent call last):
  File "/data/data/com.termux/files/usr/lib/python3.9/site-packages/flask/app.py", line 2292, in wsgi_app
    response = self.full_dispatch_request()
  File "/data/data/com.termux/files/usr/lib/python3.9/site-packages/flask/app.py", line 1815, in full_dispatch_request
    rv = self.handle_user_exception(e)
  File "/data/data/com.termux/files/usr/lib/python3.9/site-packages/flask/app.py", line 1718, in handle_user_exception
    reraise(exc_type, exc_value, tb)
  File "/data/data/com.termux/files/usr/lib/python3.9/site-packages/flask/_compat.py", line 35, in reraise
    raise value
  File "/data/data/com.termux/files/usr/lib/python3.9/site-packages/flask/app.py", line 1813, in full_dispatch_request
    rv = self.dispatch_request()
  File "/data/data/com.termux/files/usr/lib/python3.9/site-packages/flask/app.py", line 1799, in dispatch_request
    return self.view_functions[rule.endpoint](**req.view_args)
  File "/data/data/com.termux/files/usr/lib/python3.9/site-packages/flask_login/utils.py", line 228, in decorated_view
    return func(*args, **kwargs)
  File "/storage/emulated/0/python/microblog/app/routes.py", line 128, in index
    return render_template('index.html', title='Home', form=form,posts=posts.items,user=user, next_url=next_url, prev_url=prev_url,posttype=True)
  File "/data/data/com.termux/files/usr/lib/python3.9/site-packages/flask/templating.py", line 134, in render_template
    return _render(ctx.app.jinja_env.get_or_select_template(template_name_or_list),
  File "/data/data/com.termux/files/usr/lib/python3.9/site-packages/flask/templating.py", line 117, in _render
    rv = template.render(context)
  File "/data/data/com.termux/files/usr/lib/python3.9/site-packages/jinja2/asyncsupport.py", line 76, in render
    return original_render(self, *args, **kwargs)
  File "/data/data/com.termux/files/usr/lib/python3.9/site-packages/jinja2/environment.py", line 1008, in render
    return self.environment.handle_exception(exc_info, True)
  File "/data/data/com.termux/files/usr/lib/python3.9/site-packages/jinja2/environment.py", line 780, in handle_exception
    reraise(exc_type, exc_value, tb)
  File "/data/data/com.termux/files/usr/lib/python3.9/site-packages/jinja2/_compat.py", line 37, in reraise
    raise value.with_traceback(tb)
  File "/storage/emulated/0/python/microblog/app/templates/index.html", line 2, in <module>
    {% import 'bootstrap/wtf.html' as wtf %}
  File "/storage/emulated/0/python/microblog/app/templates/base.html", line 1, in <module>
    {% extends 'bootstrap/base.html' %}
  File "/data/data/com.termux/files/usr/lib/python3.9/site-packages/flask_bootstrap/templates/bootstrap/base.html", line 1, in <module>
    {% block doc -%}
  File "/data/data/com.termux/files/usr/lib/python3.9/site-packages/flask_bootstrap/templates/bootstrap/base.html", line 4, in <module>
    {%- block html %}
  File "/data/data/com.termux/files/usr/lib/python3.9/site-packages/flask_bootstrap/templates/bootstrap/base.html", line 20, in <module>
    {% block body -%}
  File "/data/data/com.termux/files/usr/lib/python3.9/site-packages/flask_bootstrap/templates/bootstrap/base.html", line 23, in <module>
    {% block content -%}
  File "/storage/emulated/0/python/microblog/app/templates/base.html", line 52, in <module>
    {% block app_content %}{% endblock %}
  File "/storage/emulated/0/python/microblog/app/templates/index.html", line 12, in <module>
    {% include '_post.html' %}
  File "/storage/emulated/0/python/microblog/app/templates/_post.html", line 5, in <module>
    <img src="{{url_for('get_image_from_db', name=post.author.username)}}" style="width: 70px">
  File "/data/data/com.termux/files/usr/lib/python3.9/site-packages/flask/helpers.py", line 356, in url_for
    return appctx.app.handle_url_build_error(error, endpoint, values)
  File "/data/data/com.termux/files/usr/lib/python3.9/site-packages/flask/app.py", line 2061, in handle_url_build_error
    reraise(exc_type, exc_value, tb)
  File "/data/data/com.termux/files/usr/lib/python3.9/site-packages/flask/_compat.py", line 35, in reraise
    raise value
  File "/data/data/com.termux/files/usr/lib/python3.9/site-packages/flask/helpers.py", line 344, in url_for
    rv = url_adapter.build(endpoint, values, method=method,
  File "/data/data/com.termux/files/usr/lib/python3.9/site-packages/werkzeug/routing.py", line 1776, in build
    raise BuildError(endpoint, values, method, self)
werkzeug.routing.BuildError: Could not build url for endpoint 'get_image_from_db' with values ['name']. Did you mean 'editmessage' instead?
2020-11-06 20:16:16,965 INFO: Microblog startup [in /storage/emulated/0/python/microblog/app/__init__.py:50]
2020-11-06 20:16:19,474 INFO: Microblog startup [in /storage/emulated/0/python/microblog/app/__init__.py:50]
