2020-11-06 20:42:44,020 ERROR: Exception on /article_1 [GET] [in /data/data/com.termux/files/usr/lib/python3.9/site-packages/flask/app.py:1758]
Traceback (most recent call last):
  File "/data/data/com.termux/files/usr/lib/python3.9/site-packages/flask/app.py", line 2292, in wsgi_app
    response = self.full_dispatch_request()
  File "/data/data/com.termux/files/usr/lib/python3.9/site-packages/flask/app.py", line 1815, in full_dispatch_request
    rv = self.handle_user_exception(e)
  File "/data/data/com.termux/files/usr/lib/python3.9/site-packages/flask/app.py", line 1718, in handle_user_exception
    reraise(exc_type, exc_value, tb)
  File "/data/data/com.termux/files/usr/lib/python3.9/site-packages/flask/_compat.py", line 35, in reraise
    raise value
  File "/data/data/com.termux/files/usr/lib/python3.9/site-packages/flask/app.py", line 1813, in full_dispatch_request
    rv = self.dispatch_request()
  File "/data/data/com.termux/files/usr/lib/python3.9/site-packages/flask/app.py", line 1799, in dispatch_request
    return self.view_functions[rule.endpoint](**req.view_args)
  File "/storage/emulated/0/python/microblog/app/routes.py", line 438, in article_1
    return render_template('telegrambotai.html',form=form,posts=posts,title='Article')
  File "/data/data/com.termux/files/usr/lib/python3.9/site-packages/flask/templating.py", line 134, in render_template
    return _render(ctx.app.jinja_env.get_or_select_template(template_name_or_list),
  File "/data/data/com.termux/files/usr/lib/python3.9/site-packages/flask/templating.py", line 117, in _render
    rv = template.render(context)
  File "/data/data/com.termux/files/usr/lib/python3.9/site-packages/jinja2/asyncsupport.py", line 76, in render
    return original_render(self, *args, **kwargs)
  File "/data/data/com.termux/files/usr/lib/python3.9/site-packages/jinja2/environment.py", line 1008, in render
    return self.environment.handle_exception(exc_info, True)
  File "/data/data/com.termux/files/usr/lib/python3.9/site-packages/jinja2/environment.py", line 780, in handle_exception
    reraise(exc_type, exc_value, tb)
  File "/data/data/com.termux/files/usr/lib/python3.9/site-packages/jinja2/_compat.py", line 37, in reraise
    raise value.with_traceback(tb)
  File "/storage/emulated/0/python/microblog/app/templates/telegrambotai.html", line 2, in <module>
    {% import 'bootstrap/wtf.html' as wtf %}
  File "/storage/emulated/0/python/microblog/app/templates/base.html", line 1, in <module>
    {% extends 'bootstrap/base.html' %}
  File "/data/data/com.termux/files/usr/lib/python3.9/site-packages/flask_bootstrap/templates/bootstrap/base.html", line 1, in <module>
    {% block doc -%}
  File "/data/data/com.termux/files/usr/lib/python3.9/site-packages/flask_bootstrap/templates/bootstrap/base.html", line 4, in <module>
    {%- block html %}
  File "/data/data/com.termux/files/usr/lib/python3.9/site-packages/flask_bootstrap/templates/bootstrap/base.html", line 20, in <module>
    {% block body -%}
  File "/data/data/com.termux/files/usr/lib/python3.9/site-packages/flask_bootstrap/templates/bootstrap/base.html", line 23, in <module>
    {% block content -%}
  File "/storage/emulated/0/python/microblog/app/templates/base.html", line 52, in <module>
    {% block app_content %}{% endblock %}
  File "/storage/emulated/0/python/microblog/app/templates/telegrambotai.html", line 103, in <module>
    <img src="/static/{{user.username}}.png" style="width: 60px">
  File "/data/data/com.termux/files/usr/lib/python3.9/site-packages/jinja2/environment.py", line 430, in getattr
    return getattr(obj, attribute)
jinja2.exceptions.UndefinedError: 'user' is undefined
2020-11-06 20:43:24,567 INFO: Microblog startup [in /storage/emulated/0/python/microblog/app/__init__.py:50]
2020-11-06 20:43:26,639 INFO: Microblog startup [in /storage/emulated/0/python/microblog/app/__init__.py:50]
2020-11-06 20:53:11,534 INFO: Microblog startup [in /storage/emulated/0/python/microblog/app/__init__.py:50]
2020-11-06 20:53:13,967 INFO: Microblog startup [in /storage/emulated/0/python/microblog/app/__init__.py:50]
2020-11-06 20:54:45,556 ERROR: Exception on /edit_profile [POST] [in /data/data/com.termux/files/usr/lib/python3.9/site-packages/flask/app.py:1758]
Traceback (most recent call last):
  File "/data/data/com.termux/files/usr/lib/python3.9/site-packages/flask/app.py", line 2292, in wsgi_app
    response = self.full_dispatch_request()
  File "/data/data/com.termux/files/usr/lib/python3.9/site-packages/flask/app.py", line 1815, in full_dispatch_request
    rv = self.handle_user_exception(e)
  File "/data/data/com.termux/files/usr/lib/python3.9/site-packages/flask/app.py", line 1718, in handle_user_exception
    reraise(exc_type, exc_value, tb)
  File "/data/data/com.termux/files/usr/lib/python3.9/site-packages/flask/_compat.py", line 35, in reraise
    raise value
  File "/data/data/com.termux/files/usr/lib/python3.9/site-packages/flask/app.py", line 1813, in full_dispatch_request
    rv = self.dispatch_request()
  File "/data/data/com.termux/files/usr/lib/python3.9/site-packages/flask/app.py", line 1799, in dispatch_request
    return self.view_functions[rule.endpoint](**req.view_args)
  File "/data/data/com.termux/files/usr/lib/python3.9/site-packages/flask_login/utils.py", line 228, in decorated_view
    return func(*args, **kwargs)
  File "/storage/emulated/0/python/microblog/app/routes.py", line 266, in edit_profile
    os.remove(previm1)
TypeError: remove: path should be string, bytes or os.PathLike, not TextIOWrapper
2020-11-06 20:59:39,144 INFO: Microblog startup [in /storage/emulated/0/python/microblog/app/__init__.py:50]
2020-11-06 20:59:53,528 INFO: Microblog startup [in /storage/emulated/0/python/microblog/app/__init__.py:50]
2020-11-06 20:59:57,086 INFO: Microblog startup [in /storage/emulated/0/python/microblog/app/__init__.py:50]
2020-11-06 21:00:17,367 ERROR: Exception on /edit_profile [POST] [in /data/data/com.termux/files/usr/lib/python3.9/site-packages/flask/app.py:1758]
Traceback (most recent call last):
  File "/data/data/com.termux/files/usr/lib/python3.9/site-packages/flask/app.py", line 2292, in wsgi_app
    response = self.full_dispatch_request()
  File "/data/data/com.termux/files/usr/lib/python3.9/site-packages/flask/app.py", line 1815, in full_dispatch_request
    rv = self.handle_user_exception(e)
  File "/data/data/com.termux/files/usr/lib/python3.9/site-packages/flask/app.py", line 1718, in handle_user_exception
    reraise(exc_type, exc_value, tb)
  File "/data/data/com.termux/files/usr/lib/python3.9/site-packages/flask/_compat.py", line 35, in reraise
    raise value
  File "/data/data/com.termux/files/usr/lib/python3.9/site-packages/flask/app.py", line 1813, in full_dispatch_request
    rv = self.dispatch_request()
  File "/data/data/com.termux/files/usr/lib/python3.9/site-packages/flask/app.py", line 1799, in dispatch_request
    return self.view_functions[rule.endpoint](**req.view_args)
  File "/data/data/com.termux/files/usr/lib/python3.9/site-packages/flask_login/utils.py", line 228, in decorated_view
    return func(*args, **kwargs)
  File "/storage/emulated/0/python/microblog/app/routes.py", line 264, in edit_profile
    if os.path.exists('app/static',current_user.username+".png"):
TypeError: exists() takes 1 positional argument but 2 were given
2020-11-06 21:03:11,690 INFO: Microblog startup [in /storage/emulated/0/python/microblog/app/__init__.py:50]
2020-11-06 21:05:18,571 INFO: Microblog startup [in /storage/emulated/0/python/microblog/app/__init__.py:50]
2020-11-06 21:08:47,128 INFO: Microblog startup [in /storage/emulated/0/python/microblog/app/__init__.py:50]
2020-11-06 21:08:53,025 INFO: Microblog startup [in /storage/emulated/0/python/microblog/app/__init__.py:50]
2020-11-06 21:09:08,547 ERROR: Exception on /edit_profile [POST] [in /data/data/com.termux/files/usr/lib/python3.9/site-packages/flask/app.py:1758]
Traceback (most recent call last):
  File "/data/data/com.termux/files/usr/lib/python3.9/site-packages/flask/app.py", line 2292, in wsgi_app
    response = self.full_dispatch_request()
  File "/data/data/com.termux/files/usr/lib/python3.9/site-packages/flask/app.py", line 1815, in full_dispatch_request
    rv = self.handle_user_exception(e)
  File "/data/data/com.termux/files/usr/lib/python3.9/site-packages/flask/app.py", line 1718, in handle_user_exception
    reraise(exc_type, exc_value, tb)
  File "/data/data/com.termux/files/usr/lib/python3.9/site-packages/flask/_compat.py", line 35, in reraise
    raise value
  File "/data/data/com.termux/files/usr/lib/python3.9/site-packages/flask/app.py", line 1813, in full_dispatch_request
    rv = self.dispatch_request()
  File "/data/data/com.termux/files/usr/lib/python3.9/site-packages/flask/app.py", line 1799, in dispatch_request
    return self.view_functions[rule.endpoint](**req.view_args)
  File "/data/data/com.termux/files/usr/lib/python3.9/site-packages/flask_login/utils.py", line 228, in decorated_view
    return func(*args, **kwargs)
  File "/storage/emulated/0/python/microblog/app/routes.py", line 264, in edit_profile
    if imgfile:
NameError: name 'imgfile' is not defined
2020-11-06 21:09:52,332 INFO: Microblog startup [in /storage/emulated/0/python/microblog/app/__init__.py:50]
2020-11-06 21:09:54,527 INFO: Microblog startup [in /storage/emulated/0/python/microblog/app/__init__.py:50]
